<?xml version="1.0" encoding="utf-8"?>
<!-- This URDF was automatically created by SolidWorks to URDF Exporter! Originally created by Stephen Brawner (brawner@gmail.com) 
     Commit Version: 1.6.0-1-g15f4949  Build Version: 1.6.7594.29634
     For more information, please see http://wiki.ros.org/sw_urdf_exporter -->
<robot name="sentinel" xmlns:xacro ="https://www.ros.org/wiki/xacro">

<xacro:include filename="$(find sentinel)/urdf/sentinel.gazebo"/>
  <link
    name="baselink">
    <inertial>
      <origin
        xyz="-0.00095975 2.4821E-05 0.03974"
        rpy="0 0 0" />
      <mass
        value="1.6022" />
      <inertia
        ixx="0.0024598"
        ixy="3.7188E-07"
        ixz="-3.0486E-08"
        iyy="0.0094916"
        iyz="-6.393E-09"
        izz="0.011737" />
    </inertial>
    <visual>
      <origin
        xyz="0 0 0"
        rpy="0 0 0" />
      <geometry>
        <mesh
          filename="package://sentinel/meshes/baselink.STL" />
      </geometry>
    

</visual>

    <collision>
      <origin
        xyz="0 0 0"
        rpy="0 0 0" />
      <geometry>
        <mesh
          filename="package://sentinel/meshes/baselink.STL" />
      </geometry>
    </collision>
  </link>

  <gazebo reference="baselink">
	  <material>Gazebo/Black</material>
  </gazebo>
  <link
    name="frontleftwheellink">
    <inertial>
      <origin
        xyz="5.9886E-10 -0.013862 -1.0386E-09"
        rpy="0 0 0" />
      <mass
        value="0.068893" />
      <inertia
        ixx="3.3866E-05"
        ixy="-4.7569E-13"
        ixz="4.7969E-10"
        iyy="4.725E-05"
        iyz="8.7884E-13"
        izz="3.3867E-05" />
    </inertial>
    <visual>
      <origin
        xyz="0 0 0"
        rpy="0 0 0" />
      <geometry>
        <mesh
          filename="package://sentinel/meshes/frontleftwheellink.STL" />
      </geometry>
    
    </visual>
    <collision>
      <origin
        xyz="0 0 0"
        rpy="0 0 0" />
      <geometry>
        <mesh
          filename="package://sentinel/meshes/frontleftwheellink.STL" />
      </geometry>
    </collision>
  </link>
    <gazebo reference="frontleftwheellink">
    <material>Gazebo/Grey</material>
  </gazebo>
  <joint
    name="frontleftjoint"
    type="continuous">
    <origin
      xyz="0.0725 0.083539 0.0175"
      rpy="0 0 0" />
    <parent
      link="baselink" />
    <child
      link="frontleftwheellink" />
    <axis
      xyz="0 -1 0" />
    <limit
      effort="100"
      velocity="100" />
  </joint>
  <link
    name="frontlefttirelink">
    <inertial>
      <origin
        xyz="-9.5103E-10 -0.013217 -7.3001E-10"
        rpy="0 0 0" />
      <mass
        value="0.068893" />
      <inertia
        ixx="3.3866E-05"
        ixy="-7.7604E-13"
        ixz="-1.1173E-13"
        iyy="4.725E-05"
        iyz="-6.2959E-13"
        izz="3.3867E-05" />
    </inertial>
    <visual>
      <origin
        xyz="0 0 0"
        rpy="0 0 0" />
      <geometry>
        <mesh
          filename="package://sentinel/meshes/frontlefttirelink.STL" />
      </geometry>
      
    </visual>
    <collision>
      <origin
        xyz="0 0 0"
        rpy="0 0 0" />
      <geometry>
        <mesh
          filename="package://sentinel/meshes/frontlefttirelink.STL" />
      </geometry>
    </collision>
  </link>
    <gazebo reference="frontlefttirelink">
    <material>Gazebo/Black</material>
  </gazebo>
  <joint
    name="frontlefttirejoint"
    type="fixed">
    <origin
      xyz="0 0 0"
      rpy="0 0 0" />
    <parent
      link="frontleftwheellink" />
    <child
      link="frontlefttirelink" />
    <axis
      xyz="0 0 0" />
    <limit
      effort="100"
      velocity="100" />
  </joint>
  <link
    name="frontrightwheellink">
    <inertial>
      <origin
        xyz="-9.5103E-10 0.013862 -7.3001E-10"
        rpy="0 0 0" />
      <mass
        value="0.068893" />
      <inertia
        ixx="3.3866E-05"
        ixy="-7.7605E-13"
        ixz="-1.1173E-13"
        iyy="4.725E-05"
        iyz="-6.2959E-13"
        izz="3.3867E-05" />
    </inertial>
    <visual>
      <origin
        xyz="0 0 0"
        rpy="0 0 0" />
      <geometry>
        <mesh
          filename="package://sentinel/meshes/frontrightwheellink.STL" />
      </geometry>
    
    </visual>
    <collision>
      <origin
        xyz="0 0 0"
        rpy="0 0 0" />
      <geometry>
        <mesh
          filename="package://sentinel/meshes/frontrightwheellink.STL" />
      </geometry>
    </collision>
  </link>
    <gazebo reference="frontrightwheellink">
    <material>Gazebo/Grey</material>
  </gazebo>
  <joint
    name="frontrightjoint"
    type="continuous">
    <origin
      xyz="0.0724999999999994 -0.0835394642490782 0.0175000000000016"
      rpy="0 0 0" />
    <parent
      link="baselink" />
    <child
      link="frontrightwheellink" />
    <axis
      xyz="0 1 0" />
    <limit
      effort="100"
      velocity="100" />
  </joint>
  <link
    name="frontrighttirelink">
    <inertial>
      <origin
        xyz="9.5103E-10 0.013217 -7.3001E-10"
        rpy="0 0 0" />
      <mass
        value="0.068893" />
      <inertia
        ixx="3.3866E-05"
        ixy="-7.7605E-13"
        ixz="1.1173E-13"
        iyy="4.725E-05"
        iyz="6.2959E-13"
        izz="3.3867E-05" />
    </inertial>
    <visual>
      <origin
        xyz="0 0 0"
        rpy="0 0 0" />
      <geometry>
        <mesh
          filename="package://sentinel/meshes/frontrighttirelink.STL" />
      </geometry>
    </visual>
    <collision>
      <origin
        xyz="0 0 0"
        rpy="0 0 0" />
      <geometry>
        <mesh
          filename="package://sentinel/meshes/frontrighttirelink.STL" />
      </geometry>
    </collision>
  </link>
    <gazebo reference="frontrighttirelink">
    <material>Gazebo/Black</material>
  </gazebo>
  <joint
    name="frontrighttirejoint"
    type="fixed">
    <origin
      xyz="0 0 0"
      rpy="0 0 0" />
    <parent
      link="frontrightwheellink" />
    <child
      link="frontrighttirelink" />
    <axis
      xyz="0 0 0" />
    <limit
      effort="100"
      velocity="100" />
  </joint>
  <link
    name="backleftwheellink">
    <inertial>
      <origin
        xyz="5.9886E-10 -0.013862 -1.0386E-09"
        rpy="0 0 0" />
      <mass
        value="0.068893" />
      <inertia
        ixx="3.3866E-05"
        ixy="-4.7569E-13"
        ixz="4.7969E-10"
        iyy="4.725E-05"
        iyz="8.7884E-13"
        izz="3.3867E-05" />
    </inertial>
    <visual>
      <origin
        xyz="0 0 0"
        rpy="0 0 0" />
      <geometry>
        <mesh
          filename="package://sentinel/meshes/backleftwheellink.STL" />
      </geometry>

    </visual>
    <collision>
      <origin
        xyz="0 0 0"
        rpy="0 0 0" />
      <geometry>
        <mesh
          filename="package://sentinel/meshes/backleftwheellink.STL" />
      </geometry>
    </collision>
  </link>
    <gazebo reference="backleftwheellink">
    <material>Gazebo/Grey</material>
  </gazebo>
  <joint
    name="backleftjoint"
    type="continuous">
    <origin
      xyz="-0.0725 0.083539 0.0175"
      rpy="0 0 0" />
    <parent
      link="baselink" />
    <child
      link="backleftwheellink" />
    <axis
      xyz="0 -1 0" />
    <limit
      effort="100"
      velocity="100" />
  </joint>
  <link
    name="backlefttirelink">
    <inertial>
      <origin
        xyz="-7.3001E-10 -0.013862 -9.5103E-10"
        rpy="0 0 0" />
      <mass
        value="0.068893" />
      <inertia
        ixx="3.3867E-05"
        ixy="6.2959E-13"
        ixz="-1.1173E-13"
        iyy="4.725E-05"
        iyz="7.7605E-13"
        izz="3.3866E-05" />
    </inertial>
    <visual>
      <origin
        xyz="0 0 0"
        rpy="0 0 0" />
      <geometry>
        <mesh
          filename="package://sentinel/meshes/backlefttirelink.STL" />
      </geometry>
    
    </visual>
    <collision>
      <origin
        xyz="0 0 0"
        rpy="0 0 0" />
      <geometry>
        <mesh
          filename="package://sentinel/meshes/backlefttirelink.STL" />
      </geometry>
    </collision>
  </link>
    <gazebo reference="backlefttirelink">
	    <material>Gazebo/Black</material>
  </gazebo>
  <joint
    name="backlefttirejoint"
    type="fixed">
    <origin
      xyz="0 0 0"
      rpy="0 0 0" />
    <parent
      link="backleftwheellink" />
    <child
      link="backlefttirelink" />
    <axis
      xyz="0 0 0" />
    <limit
      effort="100"
      velocity="100" />
  </joint>
  <link
    name="backrightwheellink">
    <inertial>
      <origin
        xyz="-9.5103E-10 0.013862 -7.3001E-10"
        rpy="0 0 0" />
      <mass
        value="0.068893" />
      <inertia
        ixx="3.3866E-05"
        ixy="-7.7605E-13"
        ixz="-1.1173E-13"
        iyy="4.725E-05"
        iyz="-6.2959E-13"
        izz="3.3867E-05" />
    </inertial>
    <visual>
      <origin
        xyz="0 0 0"
        rpy="0 0 0" />
      <geometry>
        <mesh
          filename="package://sentinel/meshes/backrightwheellink.STL" />
      </geometry>
     
    </visual>
    <collision>
      <origin
        xyz="0 0 0"
        rpy="0 0 0" />
      <geometry>
        <mesh
          filename="package://sentinel/meshes/backrightwheellink.STL" />
      </geometry>
    </collision>
  </link>
    <gazebo reference="backrightwheellink">
    <material>Gazebo/Grey</material>
  </gazebo>
  <joint
    name="backrightjoint"
    type="continuous">
    <origin
      xyz="-0.0725 -0.083539 0.0175"
      rpy="0 0 0" />
    <parent
      link="baselink" />
    <child
      link="backrightwheellink" />
    <axis
      xyz="0 1 0" />
    <limit
      effort="100"
      velocity="100" />
  </joint>
  <link
    name="backrightitrelink">
    <inertial>
      <origin
        xyz="9.5103E-10 0.013217 -7.3001E-10"
        rpy="0 0 0" />
      <mass
        value="0.068893" />
      <inertia
        ixx="3.3866E-05"
        ixy="-7.7605E-13"
        ixz="1.1173E-13"
        iyy="4.725E-05"
        iyz="6.2959E-13"
        izz="3.3867E-05" />
    </inertial>
    <visual>
      <origin
        xyz="0 0 0"
        rpy="0 0 0" />
      <geometry>
        <mesh
          filename="package://sentinel/meshes/backrightitrelink.STL" />
      </geometry>
      
    </visual>
    <collision>
      <origin
        xyz="0 0 0"
        rpy="0 0 0" />
      <geometry>
        <mesh
          filename="package://sentinel/meshes/backrightitrelink.STL" />
      </geometry>
    </collision>
  </link>
    <gazebo reference="backrightitrelink">
	    <material>Gazebo/Black</material>
  </gazebo>
  <joint
    name="backrighttirejoint"
    type="fixed">
    <origin
      xyz="0 0 0"
      rpy="0 0 0" />
    <parent
      link="backrightwheellink" />
    <child
      link="backrightitrelink" />
    <axis
      xyz="0 0 0" />
    <limit
      effort="100"
      velocity="100" />
  </joint>
  <link
    name="basemiddlelink">
    <inertial>
      <origin
        xyz="-0.00095975 2.4821E-05 0.03974"
        rpy="0 0 0" />
      <mass
        value="3.2044" />
      <inertia
        ixx="0.0049195"
        ixy="7.4377E-07"
        ixz="-6.0971E-08"
        iyy="0.018983"
        iyz="-1.2786E-08"
        izz="0.023475" />
    </inertial>
    <visual>
      <origin
        xyz="0 0 0"
        rpy="0 0 0" />
      <geometry>
        <mesh
          filename="package://sentinel/meshes/basemiddlelink.STL" />
      </geometry>
     
    </visual>
    <collision>
      <origin
        xyz="0 0 0"
        rpy="0 0 0" />
      <geometry>
        <mesh
          filename="package://sentinel/meshes/basemiddlelink.STL" />
      </geometry>
    </collision>
  </link>
    <gazebo reference="basemiddlelink">
    <material>Gazebo/Yellow</material>
  </gazebo>
  <joint
    name="basemiddlejoint"
    type="fixed">
    <origin
      xyz="0 0 0"
      rpy="0 0 0" />
    <parent
      link="baselink" />
    <child
      link="basemiddlelink" />
    <axis
      xyz="0 0 0" />
    <limit
      effort="100"
      velocity="100" />
  </joint>
  <link
    name="basetoplink">
    <inertial>
      <origin
        xyz="-0.00095975 2.4821E-05 0.03974"
        rpy="0 0 0" />
      <mass
        value="1.6022" />
      <inertia
        ixx="0.0024598"
        ixy="3.7188E-07"
        ixz="-3.0486E-08"
        iyy="0.0094916"
        iyz="-6.393E-09"
        izz="0.011737" />
    </inertial>
    <visual>
      <origin
        xyz="0 0 0"
        rpy="0 0 0" />
      <geometry>
        <mesh
          filename="package://sentinel/meshes/basetoplink.STL" />
      </geometry>
      
    </visual>
    <collision>
      <origin
        xyz="0 0 0"
        rpy="0 0 0" />
      <geometry>
        <mesh
          filename="package://sentinel/meshes/basetoplink.STL" />
      </geometry>
    </collision>
  </link>
    <gazebo reference="basetoplink">
    <material>Gazebo/Black</material>
  </gazebo>
  <joint
    name="basetopjoint"
    type="fixed">
    <origin
      xyz="0 0 0"
      rpy="0 0 0" />
    <parent
      link="basemiddlelink" />
    <child
      link="basetoplink" />
    <axis
      xyz="0 0 0" />
    <limit
      effort="100"
      velocity="100" />
  </joint>
  <link
    name="sentinelmarkinglink">
    <inertial>
      <origin
        xyz="0.00045975 -0.00052482 0.039944"
        rpy="0 0 0" />
      <mass
        value="1.6022" />
      <inertia
        ixx="0.0024598"
        ixy="3.7188E-07"
        ixz="3.0486E-08"
        iyy="0.0094916"
        iyz="6.393E-09"
        izz="0.011737" />
    </inertial>
    <visual>
      <origin
        xyz="0 0 0"
        rpy="0 0 0" />
      <geometry>
        <mesh
          filename="package://sentinel/meshes/sentinelmarkinglink.STL" />
      </geometry>
    
    </visual>
    <collision>
      <origin
        xyz="0 0 0"
        rpy="0 0 0" />
      <geometry>
        <mesh
          filename="package://sentinel/meshes/sentinelmarkinglink.STL" />
      </geometry>
    </collision>
  </link>
    <gazebo reference="sentinelmarkinglink">
    <material>Gazebo/RustySteel</material>
  </gazebo>
  <joint
    name="sentinelmarkingjoint"
    type="fixed">
    <origin
      xyz="0 0 0"
      rpy="0 0 0" />
    <parent
      link="baselink" />
    <child
      link="sentinelmarkinglink" />
    <axis
      xyz="0 0 0" />
    <limit
      effort="100"
      velocity="100" />
  </joint>


  <link name="cam1link">
      <pose>0 0 1 0 0 0</pose>
      <inertial>
        <mass>0.001</mass>
        <inertia>
          <ixx>4.166666666666667e-06</ixx>
          <iyy>5.208333333333334e-07</iyy>
          <izz>3.854166666666666e-06</izz>
        </inertia>
      </inertial>

      <visual name="visual">
        <pose>0 0 0 0 0 0</pose>
        <geometry>
         <box>
            <size>0.005 0.03 0.01</size>
         </box> 
        </geometry>
      </visual>
      <collision name="collision">
        <geometry>
          <box>
            <size>0.005 0.03 0.01</size>
          </box>
        </geometry>
      </collision>
  </link>


  <link name ='sensor_link'>
     <pose>0 0 1 0 0 0</pose>
     <inertial>
      <mass value="0.001"/>
      <inertia>
          <ixx>4.166666666666667e-06</ixx>
          <iyy>5.208333333333334e-07</iyy>
          <izz>3.854166666666666e-06</izz>
      </inertia>
     </inertial>

     <collision name='sensor_collision'>
       <geometry>
         <box>
            <size>0.003 0.01 0.01</size>
         </box>
       </geometry>
     </collision>

     <visual name='sensor_visual'>
        <pose>0 0 0 0 0 0</pose>
        <geometry>
         <box>
            <size>0.005 0.03 0.01</size>
         </box> 
        </geometry>
     </visual>
  </link>


  
  <gazebo>
    <plugin name="skid_steer_drive_controller" filename="libgazebo_ros_skid_steer_drive.so">
     <updateRate>100.0</updateRate>
     <robotNamespace>/</robotNamespace>
     <leftFrontJoint>frontleftjoint</leftFrontJoint>
     <rightFrontJoint>frontrightjoint</rightFrontJoint>
     <leftRearJoint>backleftjoint</leftRearJoint>
     <rightRearJoint>backrightjoint</rightRearJoint>
     <wheelSeparation>0.14</wheelSeparation>
     <wheelDiameter>0.06</wheelDiameter>
     <robotBaseFrame>robot_footprint</robotBaseFrame>
     <torque>200</torque>
     <MaxForce>100.0</MaxForce>
     <commandTopic>cmd_vel</commandTopic>
     <odometryTopic>odom</odometryTopic>
     <odometryFrame>odom</odometryFrame>
     <broadcastTF>true</broadcastTF>
     <covariance_x>0.001</covariance_x> 
     <covariance_y>0.001</covariance_y> 
     <covariance_yaw>0.01</covariance_yaw> 
    </plugin> 
 </gazebo>



</robot>
